<mujoco>
  <worldbody>
    <body pos="0 0 1.282" quat="-1 0 0 0" gravcomp="0" name="torso_0">
      <freejoint name="root_1" />
      <geom density="1000" type="capsule" size="0.07 0.07000002" pos="0 0 0" quat="0.7071068 0.7071068 0 0" priority="0" contype="1" conaffinity="1" group="1" condim="1" solmix="1" solref="0.015 1" solimp="0.9 0.99 0.003" margin="0" gap="0" friction="0.7 0.005 0.0001" fluidshape="none" fluidcoef="5 0.25 1.5 1 1" name="torso_2" />
      <geom density="1000" type="capsule" size="0.06 0.06000001" pos="-0.01 0 -0.12" quat="0.7071068 0.7071068 0 0" priority="0" contype="1" conaffinity="1" group="1" condim="1" solmix="1" solref="0.015 1" solimp="0.9 0.99 0.003" margin="0" gap="0" friction="0.7 0.005 0.0001" fluidshape="none" fluidcoef="5 0.25 1.5 1 1" name="waist_upper_3" />
      <body pos="0 0 0.1899999" quat="-1 0 0 0" gravcomp="0" name="head_4">
        <geom density="1000" type="sphere" size="0.09" pos="0 0 0" quat="-1 0 0 0" priority="0" contype="1" conaffinity="1" group="1" condim="1" solmix="1" solref="0.015 1" solimp="0.9 0.99 0.003" margin="0" gap="0" friction="0.7 0.005 0.0001" fluidshape="none" fluidcoef="5 0.25 1.5 1 1" name="head_8" />
      </body>
      <body pos="-0.01 0 -0.26" quat="-1 0 0 0" gravcomp="0" name="waist_lower_5">
        <joint type="hinge" pos="0 0 0.06499994" axis="-1.192093E-07 0 1" ref="0" armature="0.01" springref="0" springdamper="0 0" damping="5" stiffness="20" solreflimit="0.02 1" solimplimit="0 0.99 0.01 0.5 2" solreffriction="0.02 1" solimpfriction="0.9 0.95 0.001 0.5 2" frictionloss="0" limited="true" margin="0" range="-44.99999 44.99999" name="abdomen_z_9" />
        <joint type="hinge" pos="0 0 0.06499994" axis="-1.192093E-07 1 0" ref="0" armature="0.01" springref="0" springdamper="0 0" damping="5" stiffness="10" solreflimit="0.02 1" solimplimit="0 0.99 0.01 0.5 2" solreffriction="0.02 1" solimpfriction="0.9 0.95 0.001 0.5 2" frictionloss="0" limited="true" margin="0" range="-75.00018 30.00002" name="abdomen_y_10" />
        <geom density="1000" type="capsule" size="0.06 0.06000001" pos="0 0 0" quat="0.7071068 0.7071068 0 0" priority="0" contype="1" conaffinity="1" group="1" condim="1" solmix="1" solref="0.015 1" solimp="0.9 0.99 0.003" margin="0" gap="0" friction="0.7 0.005 0.0001" fluidshape="none" fluidcoef="5 0.25 1.5 1 1" name="waist_lower_11" />
        <body pos="0 0 -0.165" quat="-1 0 0 0" gravcomp="0" name="pelvis_12">
          <joint type="hinge" pos="0 0 0.1" axis="1 0 0" ref="0" armature="0.01" springref="0" springdamper="0 0" damping="5" stiffness="10" solreflimit="0.02 1" solimplimit="0 0.99 0.01 0.5 2" solreffriction="0.02 1" solimpfriction="0.9 0.95 0.001 0.5 2" frictionloss="0" limited="true" margin="0" range="-34.99998 34.99998" name="abdomen_x_21" />
          <geom density="1000" type="capsule" size="0.09 0.07000002" pos="-0.02 0 0" quat="0.7071068 0.7071068 0 0" priority="0" contype="1" conaffinity="1" group="1" condim="1" solmix="1" solref="0.015 1" solimp="0.9 0.99 0.003" margin="0" gap="0" friction="0.7 0.005 0.0001" fluidshape="none" fluidcoef="5 0.25 1.5 1 1" name="butt_22" />
          <body pos="0 -0.1 -0.04000002" quat="-1 0 0 0" gravcomp="0" name="thigh_right_23">
            <joint type="hinge" pos="0 0 0" axis="1 0 0" ref="0" armature="0.01" springref="0" springdamper="0 0" damping="5" stiffness="10" solreflimit="0.02 1" solimplimit="0 0.99 0.01 0.5 2" solreffriction="0.02 1" solimpfriction="0.9 0.95 0.001 0.5 2" frictionloss="0" limited="true" margin="0" range="-30.00002 10" name="hip_x_right_31" />
            <joint type="hinge" pos="0 0 0" axis="-1.192093E-07 0 1" ref="0" armature="0.01" springref="0" springdamper="0 0" damping="5" stiffness="10" solreflimit="0.02 1" solimplimit="0 0.99 0.01 0.5 2" solreffriction="0.02 1" solimpfriction="0.9 0.95 0.001 0.5 2" frictionloss="0" limited="true" margin="0" range="-60.00014 34.99998" name="hip_z_right_32" />
            <joint type="hinge" pos="0 0 0" axis="-1.192093E-07 1 0" ref="0" armature="0.01" springref="0" springdamper="0 0" damping="5" stiffness="10" solreflimit="0.02 1" solimplimit="0 0.99 0.01 0.5 2" solreffriction="0.02 1" solimpfriction="0.9 0.95 0.001 0.5 2" frictionloss="0" limited="true" margin="0" range="-149.9998 20.00001" name="hip_y_right_33" />
            <geom density="1000" type="capsule" size="0.06 0.170074" pos="0 0.005000003 -0.17" quat="0.999892 0.0147011 0 0" priority="0" contype="1" conaffinity="1" group="1" condim="1" solmix="1" solref="0.015 1" solimp="0.9 0.99 0.003" margin="0" gap="0" friction="0.7 0.005 0.0001" fluidshape="none" fluidcoef="5 0.25 1.5 1 1" name="thigh_right_34" />
            <body pos="0 0.009999998 -0.4" quat="-1 0 0 0" gravcomp="0" name="shin_right_35">
              <joint type="hinge" pos="0 0 0.02000004" axis="-1.192093E-07 -1 0" ref="0" armature="0.01" springref="0" springdamper="0 0" damping="0.2" stiffness="1" solreflimit="0.02 1" solimplimit="0 0.99 0.01 0.5 2" solreffriction="0.02 1" solimpfriction="0.9 0.95 0.001 0.5 2" frictionloss="0" limited="true" margin="0" range="-160.0002 2.000001" name="knee_right_43" />
              <geom density="1000" type="capsule" size="0.049 0.15" pos="0 0 -0.1500001" quat="-1 0 0 0" priority="0" contype="1" conaffinity="1" group="1" condim="1" solmix="1" solref="0.015 1" solimp="0.9 0.99 0.003" margin="0" gap="0" friction="0.7 0.005 0.0001" fluidshape="none" fluidcoef="5 0.25 1.5 1 1" name="shin_right_44" />
              <body pos="0 0 -0.39" quat="-1 0 0 0" gravcomp="0" name="foot_right_45">
                <joint type="hinge" pos="0 0 0.07999992" axis="-1.192093E-07 1 0" ref="0" armature="0.01" springref="0" springdamper="0 0" damping="0.2" stiffness="6" solreflimit="0.02 1" solimplimit="0 0.99 0.01 0.5 2" solreffriction="0.02 1" solimpfriction="0.9 0.95 0.001 0.5 2" frictionloss="0" limited="true" margin="0" range="-50.00002 50.00002" name="ankle_y_right_49" />
                <joint type="hinge" pos="0 0 0.03999996" axis="0.894427 0 0.447214" ref="0" armature="0.01" springref="0" springdamper="0 0" damping="0.2" stiffness="3" solreflimit="0.02 1" solimplimit="0 0.99 0.01 0.5 2" solreffriction="0.02 1" solimpfriction="0.9 0.95 0.001 0.5 2" frictionloss="0" limited="true" margin="0" range="-50.00002 50.00002" name="ankle_x_right_50" />
                <geom density="1000" type="capsule" size="0.02700001 0.105475" pos="0.035 -0.02 0" quat="0.7071068 -0.06704018 -0.7039217 0" priority="0" contype="1" conaffinity="1" group="1" condim="1" solmix="1" solref="0.015 1" solimp="0.9 0.99 0.003" margin="0" gap="0" friction="0.7 0.005 0.0001" fluidshape="none" fluidcoef="5 0.25 1.5 1 1" name="foot1_right_51" />
                <geom density="1000" type="capsule" size="0.02700001 0.105475" pos="0.035 0.02 0" quat="0.7071068 0.06704018 -0.7039217 0" priority="0" contype="1" conaffinity="1" group="1" condim="1" solmix="1" solref="0.015 1" solimp="0.9 0.99 0.003" margin="0" gap="0" friction="0.7 0.005 0.0001" fluidshape="none" fluidcoef="5 0.25 1.5 1 1" name="foot2_right_52" />
              </body>
            </body>
          </body>
          <body pos="0 0.1 -0.04000002" quat="-1 0 0 0" gravcomp="0" name="thigh_left_24">
            <joint type="hinge" pos="0 0 0" axis="-1 0 0" ref="0" armature="0.01" springref="0" springdamper="0 0" damping="5" stiffness="10" solreflimit="0.02 1" solimplimit="0 0.99 0.01 0.5 2" solreffriction="0.02 1" solimpfriction="0.9 0.95 0.001 0.5 2" frictionloss="0" limited="true" margin="0" range="-30.00002 10" name="hip_x_left_36" />
            <joint type="hinge" pos="0 0 0" axis="-1.192093E-07 0 -1" ref="0" armature="0.01" springref="0" springdamper="0 0" damping="5" stiffness="10" solreflimit="0.02 1" solimplimit="0 0.99 0.01 0.5 2" solreffriction="0.02 1" solimpfriction="0.9 0.95 0.001 0.5 2" frictionloss="0" limited="true" margin="0" range="-60.00014 34.99998" name="hip_z_left_37" />
            <joint type="hinge" pos="0 0 0" axis="-1.192093E-07 1 0" ref="0" armature="0.01" springref="0" springdamper="0 0" damping="5" stiffness="10" solreflimit="0.02 1" solimplimit="0 0.99 0.01 0.5 2" solreffriction="0.02 1" solimpfriction="0.9 0.95 0.001 0.5 2" frictionloss="0" limited="true" margin="0" range="-149.9998 20.00001" name="hip_y_left_38" />
            <geom density="1000" type="capsule" size="0.06 0.170074" pos="0 -0.005000003 -0.17" quat="0.999892 -0.0147011 0 0" priority="0" contype="1" conaffinity="1" group="1" condim="1" solmix="1" solref="0.015 1" solimp="0.9 0.99 0.003" margin="0" gap="0" friction="0.7 0.005 0.0001" fluidshape="none" fluidcoef="5 0.25 1.5 1 1" name="thigh_left_39" />
            <body pos="0 -0.009999998 -0.4" quat="-1 0 0 0" gravcomp="0" name="shin_left_40">
              <joint type="hinge" pos="0 0 0.02000004" axis="-1.192093E-07 -1 0" ref="0" armature="0.01" springref="0" springdamper="0 0" damping="0.2" stiffness="1" solreflimit="0.02 1" solimplimit="0 0.99 0.01 0.5 2" solreffriction="0.02 1" solimpfriction="0.9 0.95 0.001 0.5 2" frictionloss="0" limited="true" margin="0" range="-160.0002 2.000001" name="knee_left_46" />
              <geom density="1000" type="capsule" size="0.049 0.15" pos="0 0 -0.1500001" quat="-1 0 0 0" priority="0" contype="1" conaffinity="1" group="1" condim="1" solmix="1" solref="0.015 1" solimp="0.9 0.99 0.003" margin="0" gap="0" friction="0.7 0.005 0.0001" fluidshape="none" fluidcoef="5 0.25 1.5 1 1" name="shin_left_47" />
              <body pos="0 0 -0.39" quat="-1 0 0 0" gravcomp="0" name="foot_left_48">
                <joint type="hinge" pos="0 0 0.07999992" axis="-1.192093E-07 1 0" ref="0" armature="0.01" springref="0" springdamper="0 0" damping="0.2" stiffness="6" solreflimit="0.02 1" solimplimit="0 0.99 0.01 0.5 2" solreffriction="0.02 1" solimpfriction="0.9 0.95 0.001 0.5 2" frictionloss="0" limited="true" margin="0" range="-50.00002 50.00002" name="ankle_y_left_53" />
                <joint type="hinge" pos="0 0 0.03999996" axis="-0.8944269 0 -0.447214" ref="0" armature="0.01" springref="0" springdamper="0 0" damping="0.2" stiffness="3" solreflimit="0.02 1" solimplimit="0 0.99 0.01 0.5 2" solreffriction="0.02 1" solimpfriction="0.9 0.95 0.001 0.5 2" frictionloss="0" limited="true" margin="0" range="-50.00002 50.00002" name="ankle_x_left_54" />
                <geom density="1000" type="capsule" size="0.02700001 0.105475" pos="0.035 -0.02 0" quat="0.7071068 -0.06704018 -0.7039217 0" priority="0" contype="1" conaffinity="1" group="1" condim="1" solmix="1" solref="0.015 1" solimp="0.9 0.99 0.003" margin="0" gap="0" friction="0.7 0.005 0.0001" fluidshape="none" fluidcoef="5 0.25 1.5 1 1" name="foot1_left_55" />
                <geom density="1000" type="capsule" size="0.02700001 0.105475" pos="0.035 0.02 0" quat="0.7071068 0.06704018 -0.7039217 0" priority="0" contype="1" conaffinity="1" group="1" condim="1" solmix="1" solref="0.015 1" solimp="0.9 0.99 0.003" margin="0" gap="0" friction="0.7 0.005 0.0001" fluidshape="none" fluidcoef="5 0.25 1.5 1 1" name="foot2_left_56" />
              </body>
            </body>
          </body>
        </body>
      </body>
      <body pos="0 -0.17 0.05999994" quat="-1 0 0 0" gravcomp="0" name="upper_arm_right_6">
        <joint type="hinge" pos="0 0 0" axis="0.8164969 0.408248 0.408248" ref="0" armature="0.01" springref="0" springdamper="0 0" damping="0.2" stiffness="1" solreflimit="0.02 1" solimplimit="0 0.99 0.01 0.5 2" solreffriction="0.02 1" solimpfriction="0.9 0.95 0.001 0.5 2" frictionloss="0" limited="true" margin="0" range="-85.00001 60.00014" name="shoulder1_right_13" />
        <joint type="hinge" pos="0 0 0" axis="0 -0.7071068 0.7071068" ref="0" armature="0.01" springref="0" springdamper="0 0" damping="0.2" stiffness="1" solreflimit="0.02 1" solimplimit="0 0.99 0.01 0.5 2" solreffriction="0.02 1" solimpfriction="0.9 0.95 0.001 0.5 2" frictionloss="0" limited="true" margin="0" range="-85.00001 60.00014" name="shoulder2_right_14" />
        <geom density="1000" type="capsule" size="0.04 0.138564" pos="0.08 -0.08 -0.07999992" quat="0.8880737 -0.3250579 -0.3250579 0" priority="0" contype="1" conaffinity="1" group="1" condim="1" solmix="1" solref="0.015 1" solimp="0.9 0.99 0.003" margin="0" gap="0" friction="0.7 0.005 0.0001" fluidshape="none" fluidcoef="5 0.25 1.5 1 1" name="upper_arm_right_15" />
        <body pos="0.18 -0.18 -0.1799999" quat="-1 0 0 0" gravcomp="0" name="lower_arm_right_16">
          <joint type="hinge" pos="0 0 0" axis="0 -0.7071068 0.7071068" ref="0" armature="0.01" springref="0" springdamper="0 0" damping="0.2" stiffness="0" solreflimit="0.02 1" solimplimit="0 0.99 0.01 0.5 2" solreffriction="0.02 1" solimpfriction="0.9 0.95 0.001 0.5 2" frictionloss="0" limited="true" margin="0" range="-100 50.00002" name="elbow_right_25" />
          <geom density="1000" type="capsule" size="0.031 0.138564" pos="0.09 0.09000003 0.09000003" quat="0.459701 0.627963 -0.627963 0" priority="0" contype="1" conaffinity="1" group="1" condim="1" solmix="1" solref="0.015 1" solimp="0.9 0.99 0.003" margin="0" gap="0" friction="0.7 0.005 0.0001" fluidshape="none" fluidcoef="5 0.25 1.5 1 1" name="lower_arm_right_26" />
          <body pos="0.18 0.18 0.1799999" quat="-1 0 0 0" gravcomp="0" name="hand_right_27">
            <geom density="1000" type="sphere" size="0.04" pos="0 0 0" quat="0.8880737 -0.3250579 0.3250579 0" priority="0" contype="1" conaffinity="1" group="1" condim="1" solmix="1" solref="0.015 1" solimp="0.9 0.99 0.003" margin="0" gap="0" friction="0.7 0.005 0.0001" fluidshape="none" fluidcoef="5 0.25 1.5 1 1" name="hand_right_41" />
          </body>
        </body>
      </body>
      <body pos="0 0.17 0.05999994" quat="-1 0 0 0" gravcomp="0" name="upper_arm_left_7">
        <joint type="hinge" pos="0 0 0" axis="-0.8164969 0.4082479 -0.4082479" ref="0" armature="0.01" springref="0" springdamper="0 0" damping="0.2" stiffness="1" solreflimit="0.02 1" solimplimit="0 0.99 0.01 0.5 2" solreffriction="0.02 1" solimpfriction="0.9 0.95 0.001 0.5 2" frictionloss="0" limited="true" margin="0" range="-85.00001 60.00014" name="shoulder1_left_17" />
        <joint type="hinge" pos="0 0 0" axis="0 -0.7071068 -0.7071068" ref="0" armature="0.01" springref="0" springdamper="0 0" damping="0.2" stiffness="1" solreflimit="0.02 1" solimplimit="0 0.99 0.01 0.5 2" solreffriction="0.02 1" solimpfriction="0.9 0.95 0.001 0.5 2" frictionloss="0" limited="true" margin="0" range="-85.00001 60.00014" name="shoulder2_left_18" />
        <geom density="1000" type="capsule" size="0.04 0.138564" pos="0.08 0.08 -0.07999992" quat="0.8880737 0.3250579 -0.3250579 0" priority="0" contype="1" conaffinity="1" group="1" condim="1" solmix="1" solref="0.015 1" solimp="0.9 0.99 0.003" margin="0" gap="0" friction="0.7 0.005 0.0001" fluidshape="none" fluidcoef="5 0.25 1.5 1 1" name="upper_arm_left_19" />
        <body pos="0.18 0.18 -0.1799999" quat="-1 0 0 0" gravcomp="0" name="lower_arm_left_20">
          <joint type="hinge" pos="0 0 0" axis="0 -0.7071068 -0.7071068" ref="0" armature="0.01" springref="0" springdamper="0 0" damping="0.2" stiffness="0" solreflimit="0.02 1" solimplimit="0 0.99 0.01 0.5 2" solreffriction="0.02 1" solimpfriction="0.9 0.95 0.001 0.5 2" frictionloss="0" limited="true" margin="0" range="-100 50.00002" name="elbow_left_28" />
          <geom density="1000" type="capsule" size="0.031 0.138564" pos="0.09 -0.09000003 0.09000003" quat="0.459701 -0.627963 -0.627963 0" priority="0" contype="1" conaffinity="1" group="1" condim="1" solmix="1" solref="0.015 1" solimp="0.9 0.99 0.003" margin="0" gap="0" friction="0.7 0.005 0.0001" fluidshape="none" fluidcoef="5 0.25 1.5 1 1" name="lower_arm_left_29" />
          <body pos="0.18 -0.18 0.1799999" quat="-1 0 0 0" gravcomp="0" name="hand_left_30">
            <geom density="1000" type="sphere" size="0.04" pos="0 0 0" quat="0.8880737 0.3250579 0.3250579 0" priority="0" contype="1" conaffinity="1" group="1" condim="1" solmix="1" solref="0.015 1" solimp="0.9 0.99 0.003" margin="0" gap="0" friction="0.7 0.005 0.0001" fluidshape="none" fluidcoef="5 0.25 1.5 1 1" name="hand_left_42" />
          </body>
        </body>
      </body>
    </body>
    <geom density="1000" type="plane" size="0 0 1" pos="0 0 0" quat="-1 0 0 0" priority="0" contype="1" conaffinity="1" group="0" condim="3" solmix="1" solref="0.02 1" solimp="0.9 0.95 0.001" margin="0" gap="0" friction="1 0.005 0.0001" fluidshape="none" fluidcoef="5 0.25 1.5 1 1" name="floor_57" />
  </worldbody>
  <contact>
    <exclude body1="waist_lower_5" body2="thigh_left_24" name="exclude_1_58" />
    <exclude body1="waist_lower_5" body2="thigh_right_23" name="exclude_0_59" />
  </contact>
  <tendon>
    <fixed range="-0.3 2" solreflimit="0.02 1" solimplimit="0.9 0.95 0.001 0.5 2" solreffriction="0.02 1" solimpfriction="0.9 0.95 0.001 0.5 2" frictionloss="0" limited="true" margin="0" springlength="-1" damping="0" stiffness="0" name="hamstring_left_60">
      <joint joint="hip_y_left_38" coef="0.5" />
      <joint joint="knee_left_46" coef="-0.5" />
    </fixed>
    <fixed range="-0.3 2" solreflimit="0.02 1" solimplimit="0.9 0.95 0.001 0.5 2" solreffriction="0.02 1" solimpfriction="0.9 0.95 0.001 0.5 2" frictionloss="0" limited="true" margin="0" springlength="-1" damping="0" stiffness="0" name="hamstring_right_61">
      <joint joint="hip_y_right_33" coef="0.5" />
      <joint joint="knee_right_43" coef="-0.5" />
    </fixed>
  </tendon>
  <equality />
  <actuator>
    <general joint="abdomen_z_9" ctrllimited="true" forcelimited="false" ctrlrange="-1 1" forcerange="0 0" lengthrange="0 0" gear="40 0 0 0 0 0" dyntype="none" gaintype="fixed" biastype="none" dynprm="1 0 0" gainprm="1 0 0" biasprm="0 0 0" name="abdomen_z_62" />
    <general joint="abdomen_y_10" ctrllimited="true" forcelimited="false" ctrlrange="-1 1" forcerange="0 0" lengthrange="0 0" gear="40 0 0 0 0 0" dyntype="none" gaintype="fixed" biastype="none" dynprm="1 0 0" gainprm="1 0 0" biasprm="0 0 0" name="abdomen_y_63" />
    <general joint="abdomen_x_21" ctrllimited="true" forcelimited="false" ctrlrange="-1 1" forcerange="0 0" lengthrange="0 0" gear="40 0 0 0 0 0" dyntype="none" gaintype="fixed" biastype="none" dynprm="1 0 0" gainprm="1 0 0" biasprm="0 0 0" name="abdomen_x_64" />
    <general joint="hip_x_right_31" ctrllimited="true" forcelimited="false" ctrlrange="-1 1" forcerange="0 0" lengthrange="0 0" gear="40 0 0 0 0 0" dyntype="none" gaintype="fixed" biastype="none" dynprm="1 0 0" gainprm="1 0 0" biasprm="0 0 0" name="hip_x_right_65" />
    <general joint="hip_z_right_32" ctrllimited="true" forcelimited="false" ctrlrange="-1 1" forcerange="0 0" lengthrange="0 0" gear="40 0 0 0 0 0" dyntype="none" gaintype="fixed" biastype="none" dynprm="1 0 0" gainprm="1 0 0" biasprm="0 0 0" name="hip_z_right_66" />
    <general joint="hip_y_right_33" ctrllimited="true" forcelimited="false" ctrlrange="-1 1" forcerange="0 0" lengthrange="0 0" gear="120 0 0 0 0 0" dyntype="none" gaintype="fixed" biastype="none" dynprm="1 0 0" gainprm="1 0 0" biasprm="0 0 0" name="hip_y_right_67" />
    <general joint="knee_right_43" ctrllimited="true" forcelimited="false" ctrlrange="-1 1" forcerange="0 0" lengthrange="0 0" gear="80 0 0 0 0 0" dyntype="none" gaintype="fixed" biastype="none" dynprm="1 0 0" gainprm="1 0 0" biasprm="0 0 0" name="knee_right_68" />
    <general joint="ankle_y_right_49" ctrllimited="true" forcelimited="false" ctrlrange="-1 1" forcerange="0 0" lengthrange="0 0" gear="20 0 0 0 0 0" dyntype="none" gaintype="fixed" biastype="none" dynprm="1 0 0" gainprm="1 0 0" biasprm="0 0 0" name="ankle_y_right_69" />
    <general joint="ankle_x_right_50" ctrllimited="true" forcelimited="false" ctrlrange="-1 1" forcerange="0 0" lengthrange="0 0" gear="20 0 0 0 0 0" dyntype="none" gaintype="fixed" biastype="none" dynprm="1 0 0" gainprm="1 0 0" biasprm="0 0 0" name="ankle_x_right_70" />
    <general joint="hip_x_left_36" ctrllimited="true" forcelimited="false" ctrlrange="-1 1" forcerange="0 0" lengthrange="0 0" gear="40 0 0 0 0 0" dyntype="none" gaintype="fixed" biastype="none" dynprm="1 0 0" gainprm="1 0 0" biasprm="0 0 0" name="hip_x_left_71" />
    <general joint="hip_z_left_37" ctrllimited="true" forcelimited="false" ctrlrange="-1 1" forcerange="0 0" lengthrange="0 0" gear="40 0 0 0 0 0" dyntype="none" gaintype="fixed" biastype="none" dynprm="1 0 0" gainprm="1 0 0" biasprm="0 0 0" name="hip_z_left_72" />
    <general joint="hip_y_left_38" ctrllimited="true" forcelimited="false" ctrlrange="-1 1" forcerange="0 0" lengthrange="0 0" gear="120 0 0 0 0 0" dyntype="none" gaintype="fixed" biastype="none" dynprm="1 0 0" gainprm="1 0 0" biasprm="0 0 0" name="hip_y_left_73" />
    <general joint="knee_left_46" ctrllimited="true" forcelimited="false" ctrlrange="-1 1" forcerange="0 0" lengthrange="0 0" gear="80 0 0 0 0 0" dyntype="none" gaintype="fixed" biastype="none" dynprm="1 0 0" gainprm="1 0 0" biasprm="0 0 0" name="knee_left_74" />
    <general joint="ankle_y_left_53" ctrllimited="true" forcelimited="false" ctrlrange="-1 1" forcerange="0 0" lengthrange="0 0" gear="20 0 0 0 0 0" dyntype="none" gaintype="fixed" biastype="none" dynprm="1 0 0" gainprm="1 0 0" biasprm="0 0 0" name="ankle_y_left_75" />
    <general joint="ankle_x_left_54" ctrllimited="true" forcelimited="false" ctrlrange="-1 1" forcerange="0 0" lengthrange="0 0" gear="20 0 0 0 0 0" dyntype="none" gaintype="fixed" biastype="none" dynprm="1 0 0" gainprm="1 0 0" biasprm="0 0 0" name="ankle_x_left_76" />
    <general joint="shoulder1_right_13" ctrllimited="true" forcelimited="false" ctrlrange="-1 1" forcerange="0 0" lengthrange="0 0" gear="20 0 0 0 0 0" dyntype="none" gaintype="fixed" biastype="none" dynprm="1 0 0" gainprm="1 0 0" biasprm="0 0 0" name="shoulder1_right_77" />
    <general joint="shoulder2_right_14" ctrllimited="true" forcelimited="false" ctrlrange="-1 1" forcerange="0 0" lengthrange="0 0" gear="20 0 0 0 0 0" dyntype="none" gaintype="fixed" biastype="none" dynprm="1 0 0" gainprm="1 0 0" biasprm="0 0 0" name="shoulder2_right_78" />
    <general joint="elbow_right_25" ctrllimited="true" forcelimited="false" ctrlrange="-1 1" forcerange="0 0" lengthrange="0 0" gear="40 0 0 0 0 0" dyntype="none" gaintype="fixed" biastype="none" dynprm="1 0 0" gainprm="1 0 0" biasprm="0 0 0" name="elbow_right_79" />
    <general joint="shoulder1_left_17" ctrllimited="true" forcelimited="false" ctrlrange="-1 1" forcerange="0 0" lengthrange="0 0" gear="20 0 0 0 0 0" dyntype="none" gaintype="fixed" biastype="none" dynprm="1 0 0" gainprm="1 0 0" biasprm="0 0 0" name="shoulder1_left_80" />
    <general joint="shoulder2_left_18" ctrllimited="true" forcelimited="false" ctrlrange="-1 1" forcerange="0 0" lengthrange="0 0" gear="20 0 0 0 0 0" dyntype="none" gaintype="fixed" biastype="none" dynprm="1 0 0" gainprm="1 0 0" biasprm="0 0 0" name="shoulder2_left_81" />
    <general joint="elbow_left_28" ctrllimited="true" forcelimited="false" ctrlrange="-1 1" forcerange="0 0" lengthrange="0 0" gear="40 0 0 0 0 0" dyntype="none" gaintype="fixed" biastype="none" dynprm="1 0 0" gainprm="1 0 0" biasprm="0 0 0" name="elbow_left_82" />
  </actuator>
  <sensor />
  <compiler coordinate="local" />
  <option gravity="0 0 -9.81" timestep="0.01999999" />
  <option impratio="1" magnetic="0 0 0" wind="0 0 0" density="0" viscosity="0" o_margin="0" o_solref="0.02 1" o_solimp="0.9 0.95 0.001 0.5 2" integrator="Euler" cone="pyramidal" jacobian="auto" solver="Newton" iterations="100" tolerance="1E-08" noslip_iterations="0" noslip_tolerance="1E-06" ccd_iterations="50" ccd_tolerance="1E-06">
    <flag constraint="enable" equality="enable" frictionloss="enable" limit="enable" contact="enable" passive="enable" gravity="enable" clampctrl="enable" warmstart="enable" filterparent="enable" actuation="enable" refsafe="enable" override="disable" energy="disable" fwdinv="disable" multiccd="disable" />
  </option>
  <size memory="-1" />
  <custom />
  <asset />
</mujoco>